2021-01-27 23:50:42 httpbin_validator.py [line:103] ERROR: 'Proxy' object has no attribute 'get'
Traceback (most recent call last):
  File "D:/07python_auto/04IPProxyPool/core/proxy_validate/httpbin_validator.py", line 81, in _check_http_proxies
    response = requests.get(test_url,headers=get_request_headers(),proxies=proxies,timeout=TEST_TIMEOUT)
  File "C:\Users\12139\AppData\Local\Programs\Python\Python37\lib\requests\api.py", line 76, in get
    return request('get', url, params=params, **kwargs)
  File "C:\Users\12139\AppData\Local\Programs\Python\Python37\lib\requests\api.py", line 61, in request
    return session.request(method=method, url=url, **kwargs)
  File "C:\Users\12139\AppData\Local\Programs\Python\Python37\lib\requests\sessions.py", line 521, in request
    prep.url, proxies, stream, verify, cert
  File "C:\Users\12139\AppData\Local\Programs\Python\Python37\lib\requests\sessions.py", line 696, in merge_environment_settings
    no_proxy = proxies.get('no_proxy') if proxies is not None else None
AttributeError: 'Proxy' object has no attribute 'get'
2021-01-27 23:51:33 httpbin_validator.py [line:103] ERROR: 'Proxy' object has no attribute 'get'
Traceback (most recent call last):
  File "D:/07python_auto/04IPProxyPool/core/proxy_validate/httpbin_validator.py", line 81, in _check_http_proxies
    response = requests.get(test_url,headers=get_request_headers(),proxies=proxies,timeout=TEST_TIMEOUT)
  File "C:\Users\12139\AppData\Local\Programs\Python\Python37\lib\requests\api.py", line 76, in get
    return request('get', url, params=params, **kwargs)
  File "C:\Users\12139\AppData\Local\Programs\Python\Python37\lib\requests\api.py", line 61, in request
    return session.request(method=method, url=url, **kwargs)
  File "C:\Users\12139\AppData\Local\Programs\Python\Python37\lib\requests\sessions.py", line 521, in request
    prep.url, proxies, stream, verify, cert
  File "C:\Users\12139\AppData\Local\Programs\Python\Python37\lib\requests\sessions.py", line 696, in merge_environment_settings
    no_proxy = proxies.get('no_proxy') if proxies is not None else None
AttributeError: 'Proxy' object has no attribute 'get'
2021-01-27 23:52:48 httpbin_validator.py [line:103] ERROR: 'Proxy' object has no attribute 'get'
Traceback (most recent call last):
  File "D:/07python_auto/04IPProxyPool/core/proxy_validate/httpbin_validator.py", line 81, in _check_http_proxies
    response = requests.get(test_url,headers=get_request_headers(),proxies=proxies,timeout=TEST_TIMEOUT)
  File "C:\Users\12139\AppData\Local\Programs\Python\Python37\lib\requests\api.py", line 76, in get
    return request('get', url, params=params, **kwargs)
  File "C:\Users\12139\AppData\Local\Programs\Python\Python37\lib\requests\api.py", line 61, in request
    return session.request(method=method, url=url, **kwargs)
  File "C:\Users\12139\AppData\Local\Programs\Python\Python37\lib\requests\sessions.py", line 521, in request
    prep.url, proxies, stream, verify, cert
  File "C:\Users\12139\AppData\Local\Programs\Python\Python37\lib\requests\sessions.py", line 696, in merge_environment_settings
    no_proxy = proxies.get('no_proxy') if proxies is not None else None
AttributeError: 'Proxy' object has no attribute 'get'
2021-01-27 23:53:21 httpbin_validator.py [line:103] ERROR: 'Proxy' object has no attribute 'get'
Traceback (most recent call last):
  File "D:/07python_auto/04IPProxyPool/core/proxy_validate/httpbin_validator.py", line 81, in _check_http_proxies
    response = requests.get(test_url,headers=get_request_headers(),proxies=proxies,timeout=TEST_TIMEOUT)
  File "C:\Users\12139\AppData\Local\Programs\Python\Python37\lib\requests\api.py", line 76, in get
    return request('get', url, params=params, **kwargs)
  File "C:\Users\12139\AppData\Local\Programs\Python\Python37\lib\requests\api.py", line 61, in request
    return session.request(method=method, url=url, **kwargs)
  File "C:\Users\12139\AppData\Local\Programs\Python\Python37\lib\requests\sessions.py", line 521, in request
    prep.url, proxies, stream, verify, cert
  File "C:\Users\12139\AppData\Local\Programs\Python\Python37\lib\requests\sessions.py", line 696, in merge_environment_settings
    no_proxy = proxies.get('no_proxy') if proxies is not None else None
AttributeError: 'Proxy' object has no attribute 'get'
2021-01-27 23:58:08 httpbin_validator.py [line:103] ERROR: 'Proxy' object has no attribute 'get'
Traceback (most recent call last):
  File "D:/07python_auto/04IPProxyPool/core/proxy_validate/httpbin_validator.py", line 81, in _check_http_proxies
    response = requests.get(test_url,headers=get_request_headers(),proxies=proxies,timeout=TEST_TIMEOUT)
  File "C:\Users\12139\AppData\Local\Programs\Python\Python37\lib\requests\api.py", line 76, in get
    return request('get', url, params=params, **kwargs)
  File "C:\Users\12139\AppData\Local\Programs\Python\Python37\lib\requests\api.py", line 61, in request
    return session.request(method=method, url=url, **kwargs)
  File "C:\Users\12139\AppData\Local\Programs\Python\Python37\lib\requests\sessions.py", line 521, in request
    prep.url, proxies, stream, verify, cert
  File "C:\Users\12139\AppData\Local\Programs\Python\Python37\lib\requests\sessions.py", line 696, in merge_environment_settings
    no_proxy = proxies.get('no_proxy') if proxies is not None else None
AttributeError: 'Proxy' object has no attribute 'get'
2021-01-28 00:00:43 httpbin_validator.py [line:103] ERROR: 'Proxy' object has no attribute 'get'
Traceback (most recent call last):
  File "D:/07python_auto/04IPProxyPool/core/proxy_validate/httpbin_validator.py", line 81, in _check_http_proxies
    response = requests.get(test_url,headers=get_request_headers(),proxies=proxies,timeout=TEST_TIMEOUT)
  File "C:\Users\12139\AppData\Local\Programs\Python\Python37\lib\requests\api.py", line 76, in get
    return request('get', url, params=params, **kwargs)
  File "C:\Users\12139\AppData\Local\Programs\Python\Python37\lib\requests\api.py", line 61, in request
    return session.request(method=method, url=url, **kwargs)
  File "C:\Users\12139\AppData\Local\Programs\Python\Python37\lib\requests\sessions.py", line 521, in request
    prep.url, proxies, stream, verify, cert
  File "C:\Users\12139\AppData\Local\Programs\Python\Python37\lib\requests\sessions.py", line 696, in merge_environment_settings
    no_proxy = proxies.get('no_proxy') if proxies is not None else None
AttributeError: 'Proxy' object has no attribute 'get'
2021-01-28 00:02:51 httpbin_validator.py [line:103] ERROR: 'Proxy' object has no attribute 'get'
Traceback (most recent call last):
  File "D:/07python_auto/04IPProxyPool/core/proxy_validate/httpbin_validator.py", line 81, in _check_http_proxies
    response = requests.get(test_url,headers=get_request_headers(),proxies=proxies,timeout=TEST_TIMEOUT)
  File "C:\Users\12139\AppData\Local\Programs\Python\Python37\lib\requests\api.py", line 76, in get
    return request('get', url, params=params, **kwargs)
  File "C:\Users\12139\AppData\Local\Programs\Python\Python37\lib\requests\api.py", line 61, in request
    return session.request(method=method, url=url, **kwargs)
  File "C:\Users\12139\AppData\Local\Programs\Python\Python37\lib\requests\sessions.py", line 521, in request
    prep.url, proxies, stream, verify, cert
  File "C:\Users\12139\AppData\Local\Programs\Python\Python37\lib\requests\sessions.py", line 696, in merge_environment_settings
    no_proxy = proxies.get('no_proxy') if proxies is not None else None
AttributeError: 'Proxy' object has no attribute 'get'
2021-01-28 00:03:04 httpbin_validator.py [line:103] ERROR: 'Proxy' object has no attribute 'get'
Traceback (most recent call last):
  File "D:/07python_auto/04IPProxyPool/core/proxy_validate/httpbin_validator.py", line 81, in _check_http_proxies
    response = requests.get(test_url,headers=get_request_headers(),proxies=proxies,timeout=TEST_TIMEOUT)
  File "C:\Users\12139\AppData\Local\Programs\Python\Python37\lib\requests\api.py", line 76, in get
    return request('get', url, params=params, **kwargs)
  File "C:\Users\12139\AppData\Local\Programs\Python\Python37\lib\requests\api.py", line 61, in request
    return session.request(method=method, url=url, **kwargs)
  File "C:\Users\12139\AppData\Local\Programs\Python\Python37\lib\requests\sessions.py", line 521, in request
    prep.url, proxies, stream, verify, cert
  File "C:\Users\12139\AppData\Local\Programs\Python\Python37\lib\requests\sessions.py", line 696, in merge_environment_settings
    no_proxy = proxies.get('no_proxy') if proxies is not None else None
AttributeError: 'Proxy' object has no attribute 'get'
2021-01-28 00:08:33 httpbin_validator.py [line:103] ERROR: 'Proxy' object has no attribute 'get'
Traceback (most recent call last):
  File "D:/07python_auto/04IPProxyPool/core/proxy_validate/httpbin_validator.py", line 81, in _check_http_proxies
    response = requests.get(test_url,headers=get_request_headers(),proxies=proxies,timeout=TEST_TIMEOUT)
  File "C:\Users\12139\AppData\Local\Programs\Python\Python37\lib\requests\api.py", line 76, in get
    return request('get', url, params=params, **kwargs)
  File "C:\Users\12139\AppData\Local\Programs\Python\Python37\lib\requests\api.py", line 61, in request
    return session.request(method=method, url=url, **kwargs)
  File "C:\Users\12139\AppData\Local\Programs\Python\Python37\lib\requests\sessions.py", line 521, in request
    prep.url, proxies, stream, verify, cert
  File "C:\Users\12139\AppData\Local\Programs\Python\Python37\lib\requests\sessions.py", line 696, in merge_environment_settings
    no_proxy = proxies.get('no_proxy') if proxies is not None else None
AttributeError: 'Proxy' object has no attribute 'get'
2021-01-28 00:08:59 httpbin_validator.py [line:103] ERROR: 'Proxy' object has no attribute 'get'
Traceback (most recent call last):
  File "D:/07python_auto/04IPProxyPool/core/proxy_validate/httpbin_validator.py", line 81, in _check_http_proxies
    response = requests.get(test_url,headers=get_request_headers(),proxies=proxies,timeout=TEST_TIMEOUT)
  File "C:\Users\12139\AppData\Local\Programs\Python\Python37\lib\requests\api.py", line 76, in get
    return request('get', url, params=params, **kwargs)
  File "C:\Users\12139\AppData\Local\Programs\Python\Python37\lib\requests\api.py", line 61, in request
    return session.request(method=method, url=url, **kwargs)
  File "C:\Users\12139\AppData\Local\Programs\Python\Python37\lib\requests\sessions.py", line 521, in request
    prep.url, proxies, stream, verify, cert
  File "C:\Users\12139\AppData\Local\Programs\Python\Python37\lib\requests\sessions.py", line 696, in merge_environment_settings
    no_proxy = proxies.get('no_proxy') if proxies is not None else None
AttributeError: 'Proxy' object has no attribute 'get'
2021-01-28 00:09:12 httpbin_validator.py [line:103] ERROR: 'Proxy' object has no attribute 'get'
Traceback (most recent call last):
  File "D:/07python_auto/04IPProxyPool/core/proxy_validate/httpbin_validator.py", line 81, in _check_http_proxies
    response = requests.get(test_url,headers=get_request_headers(),proxies=proxies,timeout=TEST_TIMEOUT)
  File "C:\Users\12139\AppData\Local\Programs\Python\Python37\lib\requests\api.py", line 76, in get
    return request('get', url, params=params, **kwargs)
  File "C:\Users\12139\AppData\Local\Programs\Python\Python37\lib\requests\api.py", line 61, in request
    return session.request(method=method, url=url, **kwargs)
  File "C:\Users\12139\AppData\Local\Programs\Python\Python37\lib\requests\sessions.py", line 521, in request
    prep.url, proxies, stream, verify, cert
  File "C:\Users\12139\AppData\Local\Programs\Python\Python37\lib\requests\sessions.py", line 696, in merge_environment_settings
    no_proxy = proxies.get('no_proxy') if proxies is not None else None
AttributeError: 'Proxy' object has no attribute 'get'
2021-01-28 00:14:28 httpbin_validator.py [line:103] ERROR: 'Proxy' object has no attribute 'get'
Traceback (most recent call last):
  File "D:/07python_auto/04IPProxyPool/core/proxy_validate/httpbin_validator.py", line 81, in _check_http_proxies
    response = requests.get(test_url,headers=get_request_headers(),proxies=proxies,timeout=TEST_TIMEOUT)
  File "C:\Users\12139\AppData\Local\Programs\Python\Python37\lib\requests\api.py", line 76, in get
    return request('get', url, params=params, **kwargs)
  File "C:\Users\12139\AppData\Local\Programs\Python\Python37\lib\requests\api.py", line 61, in request
    return session.request(method=method, url=url, **kwargs)
  File "C:\Users\12139\AppData\Local\Programs\Python\Python37\lib\requests\sessions.py", line 521, in request
    prep.url, proxies, stream, verify, cert
  File "C:\Users\12139\AppData\Local\Programs\Python\Python37\lib\requests\sessions.py", line 696, in merge_environment_settings
    no_proxy = proxies.get('no_proxy') if proxies is not None else None
AttributeError: 'Proxy' object has no attribute 'get'
2021-02-21 22:16:36 httpbin_validator.py [line:103] ERROR: 'Proxy' object has no attribute 'get'
Traceback (most recent call last):
  File "D:/07python_auto/04IPProxyPool/core/proxy_validate/httpbin_validator.py", line 81, in _check_http_proxies
    response = requests.get(test_url,headers=get_request_headers(),proxies=proxies,timeout=TEST_TIMEOUT)
  File "C:\Users\12139\AppData\Local\Programs\Python\Python37\lib\requests\api.py", line 76, in get
    return request('get', url, params=params, **kwargs)
  File "C:\Users\12139\AppData\Local\Programs\Python\Python37\lib\requests\api.py", line 61, in request
    return session.request(method=method, url=url, **kwargs)
  File "C:\Users\12139\AppData\Local\Programs\Python\Python37\lib\requests\sessions.py", line 521, in request
    prep.url, proxies, stream, verify, cert
  File "C:\Users\12139\AppData\Local\Programs\Python\Python37\lib\requests\sessions.py", line 696, in merge_environment_settings
    no_proxy = proxies.get('no_proxy') if proxies is not None else None
AttributeError: 'Proxy' object has no attribute 'get'
2021-02-21 22:32:10 httpbin_validator.py [line:104] ERROR: 'Proxy' object has no attribute 'get'
Traceback (most recent call last):
  File "D:/07python_auto/04IPProxyPool/core/proxy_validate/httpbin_validator.py", line 81, in _check_http_proxies
    response = requests.get(test_url,headers=get_request_headers(),proxies=proxies,timeout=TEST_TIMEOUT)
  File "C:\Users\12139\AppData\Local\Programs\Python\Python37\lib\requests\api.py", line 76, in get
    return request('get', url, params=params, **kwargs)
  File "C:\Users\12139\AppData\Local\Programs\Python\Python37\lib\requests\api.py", line 61, in request
    return session.request(method=method, url=url, **kwargs)
  File "C:\Users\12139\AppData\Local\Programs\Python\Python37\lib\requests\sessions.py", line 521, in request
    prep.url, proxies, stream, verify, cert
  File "C:\Users\12139\AppData\Local\Programs\Python\Python37\lib\requests\sessions.py", line 696, in merge_environment_settings
    no_proxy = proxies.get('no_proxy') if proxies is not None else None
AttributeError: 'Proxy' object has no attribute 'get'
2021-02-21 22:33:32 httpbin_validator.py [line:104] ERROR: 'Proxy' object has no attribute 'get'
Traceback (most recent call last):
  File "D:/07python_auto/04IPProxyPool/core/proxy_validate/httpbin_validator.py", line 81, in _check_http_proxies
    response = requests.get(test_url,headers=get_request_headers(),proxies=proxies,timeout=TEST_TIMEOUT)
  File "C:\Users\12139\AppData\Local\Programs\Python\Python37\lib\requests\api.py", line 76, in get
    return request('get', url, params=params, **kwargs)
  File "C:\Users\12139\AppData\Local\Programs\Python\Python37\lib\requests\api.py", line 61, in request
    return session.request(method=method, url=url, **kwargs)
  File "C:\Users\12139\AppData\Local\Programs\Python\Python37\lib\requests\sessions.py", line 521, in request
    prep.url, proxies, stream, verify, cert
  File "C:\Users\12139\AppData\Local\Programs\Python\Python37\lib\requests\sessions.py", line 696, in merge_environment_settings
    no_proxy = proxies.get('no_proxy') if proxies is not None else None
AttributeError: 'Proxy' object has no attribute 'get'
2021-02-21 22:45:36 httpbin_validator.py [line:103] ERROR: 'Proxy' object has no attribute 'get'
Traceback (most recent call last):
  File "D:/07python_auto/04IPProxyPool/core/proxy_validate/httpbin_validator.py", line 81, in _check_http_proxies
    response = requests.get(test_url,headers=get_request_headers(),proxies=proxies,timeout=TEST_TIMEOUT)
  File "C:\Users\12139\AppData\Local\Programs\Python\Python37\lib\requests\api.py", line 76, in get
    return request('get', url, params=params, **kwargs)
  File "C:\Users\12139\AppData\Local\Programs\Python\Python37\lib\requests\api.py", line 61, in request
    return session.request(method=method, url=url, **kwargs)
  File "C:\Users\12139\AppData\Local\Programs\Python\Python37\lib\requests\sessions.py", line 521, in request
    prep.url, proxies, stream, verify, cert
  File "C:\Users\12139\AppData\Local\Programs\Python\Python37\lib\requests\sessions.py", line 696, in merge_environment_settings
    no_proxy = proxies.get('no_proxy') if proxies is not None else None
AttributeError: 'Proxy' object has no attribute 'get'
2021-02-21 22:55:47 httpbin_validator.py [line:103] ERROR: 'Proxy' object has no attribute 'get'
Traceback (most recent call last):
  File "D:/07python_auto/04IPProxyPool/core/proxy_validate/httpbin_validator.py", line 81, in _check_http_proxies
    response = requests.get(test_url,headers=get_request_headers(),proxies=proxies,timeout=TEST_TIMEOUT)
  File "C:\Users\12139\AppData\Local\Programs\Python\Python37\lib\requests\api.py", line 76, in get
    return request('get', url, params=params, **kwargs)
  File "C:\Users\12139\AppData\Local\Programs\Python\Python37\lib\requests\api.py", line 61, in request
    return session.request(method=method, url=url, **kwargs)
  File "C:\Users\12139\AppData\Local\Programs\Python\Python37\lib\requests\sessions.py", line 521, in request
    prep.url, proxies, stream, verify, cert
  File "C:\Users\12139\AppData\Local\Programs\Python\Python37\lib\requests\sessions.py", line 696, in merge_environment_settings
    no_proxy = proxies.get('no_proxy') if proxies is not None else None
AttributeError: 'Proxy' object has no attribute 'get'
2021-02-21 22:56:40 httpbin_validator.py [line:103] ERROR: 'Proxy' object has no attribute 'get'
Traceback (most recent call last):
  File "D:/07python_auto/04IPProxyPool/core/proxy_validate/httpbin_validator.py", line 81, in _check_http_proxies
    response = requests.get(test_url,headers=get_request_headers(),proxies=proxies,timeout=TEST_TIMEOUT)
  File "C:\Users\12139\AppData\Local\Programs\Python\Python37\lib\requests\api.py", line 76, in get
    return request('get', url, params=params, **kwargs)
  File "C:\Users\12139\AppData\Local\Programs\Python\Python37\lib\requests\api.py", line 61, in request
    return session.request(method=method, url=url, **kwargs)
  File "C:\Users\12139\AppData\Local\Programs\Python\Python37\lib\requests\sessions.py", line 521, in request
    prep.url, proxies, stream, verify, cert
  File "C:\Users\12139\AppData\Local\Programs\Python\Python37\lib\requests\sessions.py", line 696, in merge_environment_settings
    no_proxy = proxies.get('no_proxy') if proxies is not None else None
AttributeError: 'Proxy' object has no attribute 'get'
2021-02-21 23:00:10 httpbin_validator.py [line:103] ERROR: 'Proxy' object has no attribute 'get'
Traceback (most recent call last):
  File "D:/07python_auto/04IPProxyPool/core/proxy_validate/httpbin_validator.py", line 81, in _check_http_proxies
    response = requests.get(test_url,headers=get_request_headers(),proxies=proxies,timeout=TEST_TIMEOUT)
  File "C:\Users\12139\AppData\Local\Programs\Python\Python37\lib\requests\api.py", line 76, in get
    return request('get', url, params=params, **kwargs)
  File "C:\Users\12139\AppData\Local\Programs\Python\Python37\lib\requests\api.py", line 61, in request
    return session.request(method=method, url=url, **kwargs)
  File "C:\Users\12139\AppData\Local\Programs\Python\Python37\lib\requests\sessions.py", line 521, in request
    prep.url, proxies, stream, verify, cert
  File "C:\Users\12139\AppData\Local\Programs\Python\Python37\lib\requests\sessions.py", line 696, in merge_environment_settings
    no_proxy = proxies.get('no_proxy') if proxies is not None else None
AttributeError: 'Proxy' object has no attribute 'get'
2021-02-21 23:03:39 httpbin_validator.py [line:104] ERROR: 'Proxy' object has no attribute 'get'
Traceback (most recent call last):
  File "D:/07python_auto/04IPProxyPool/core/proxy_validate/httpbin_validator.py", line 81, in _check_http_proxies
    response = requests.get(test_url,headers=get_request_headers(),proxies=proxies,timeout=TEST_TIMEOUT)
  File "C:\Users\12139\AppData\Local\Programs\Python\Python37\lib\requests\api.py", line 76, in get
    return request('get', url, params=params, **kwargs)
  File "C:\Users\12139\AppData\Local\Programs\Python\Python37\lib\requests\api.py", line 61, in request
    return session.request(method=method, url=url, **kwargs)
  File "C:\Users\12139\AppData\Local\Programs\Python\Python37\lib\requests\sessions.py", line 521, in request
    prep.url, proxies, stream, verify, cert
  File "C:\Users\12139\AppData\Local\Programs\Python\Python37\lib\requests\sessions.py", line 696, in merge_environment_settings
    no_proxy = proxies.get('no_proxy') if proxies is not None else None
AttributeError: 'Proxy' object has no attribute 'get'
2021-02-21 23:11:18 httpbin_validator.py [line:104] ERROR: 'Proxy' object has no attribute 'get'
Traceback (most recent call last):
  File "D:/07python_auto/04IPProxyPool/core/proxy_validate/httpbin_validator.py", line 81, in _check_http_proxies
    response = requests.get(test_url,headers=get_request_headers(),proxies=proxies,timeout=TEST_TIMEOUT)
  File "C:\Users\12139\AppData\Local\Programs\Python\Python37\lib\requests\api.py", line 76, in get
    return request('get', url, params=params, **kwargs)
  File "C:\Users\12139\AppData\Local\Programs\Python\Python37\lib\requests\api.py", line 61, in request
    return session.request(method=method, url=url, **kwargs)
  File "C:\Users\12139\AppData\Local\Programs\Python\Python37\lib\requests\sessions.py", line 521, in request
    prep.url, proxies, stream, verify, cert
  File "C:\Users\12139\AppData\Local\Programs\Python\Python37\lib\requests\sessions.py", line 696, in merge_environment_settings
    no_proxy = proxies.get('no_proxy') if proxies is not None else None
AttributeError: 'Proxy' object has no attribute 'get'
2021-02-21 23:21:26 httpbin_validator.py [line:104] ERROR: 'Proxy' object has no attribute 'get'
Traceback (most recent call last):
  File "D:/07python_auto/04IPProxyPool/core/proxy_validate/httpbin_validator.py", line 81, in _check_http_proxies
    response = requests.get(test_url,headers=get_request_headers(),proxies=proxies,timeout=TEST_TIMEOUT)
  File "C:\Users\12139\AppData\Local\Programs\Python\Python37\lib\requests\api.py", line 76, in get
    return request('get', url, params=params, **kwargs)
  File "C:\Users\12139\AppData\Local\Programs\Python\Python37\lib\requests\api.py", line 61, in request
    return session.request(method=method, url=url, **kwargs)
  File "C:\Users\12139\AppData\Local\Programs\Python\Python37\lib\requests\sessions.py", line 521, in request
    prep.url, proxies, stream, verify, cert
  File "C:\Users\12139\AppData\Local\Programs\Python\Python37\lib\requests\sessions.py", line 696, in merge_environment_settings
    no_proxy = proxies.get('no_proxy') if proxies is not None else None
AttributeError: 'Proxy' object has no attribute 'get'
2021-02-21 23:21:34 httpbin_validator.py [line:104] ERROR: 'Proxy' object has no attribute 'get'
Traceback (most recent call last):
  File "D:/07python_auto/04IPProxyPool/core/proxy_validate/httpbin_validator.py", line 81, in _check_http_proxies
    response = requests.get(test_url,headers=get_request_headers(),proxies=proxies,timeout=TEST_TIMEOUT)
  File "C:\Users\12139\AppData\Local\Programs\Python\Python37\lib\requests\api.py", line 76, in get
    return request('get', url, params=params, **kwargs)
  File "C:\Users\12139\AppData\Local\Programs\Python\Python37\lib\requests\api.py", line 61, in request
    return session.request(method=method, url=url, **kwargs)
  File "C:\Users\12139\AppData\Local\Programs\Python\Python37\lib\requests\sessions.py", line 521, in request
    prep.url, proxies, stream, verify, cert
  File "C:\Users\12139\AppData\Local\Programs\Python\Python37\lib\requests\sessions.py", line 696, in merge_environment_settings
    no_proxy = proxies.get('no_proxy') if proxies is not None else None
AttributeError: 'Proxy' object has no attribute 'get'
2021-02-21 23:28:21 httpbin_validator.py [line:104] ERROR: 'Proxy' object has no attribute 'get'
Traceback (most recent call last):
  File "D:/07python_auto/04IPProxyPool/core/proxy_validate/httpbin_validator.py", line 81, in _check_http_proxies
    response = requests.get(test_url,headers=get_request_headers(),proxies=proxies,timeout=TEST_TIMEOUT)
  File "C:\Users\12139\AppData\Local\Programs\Python\Python37\lib\requests\api.py", line 76, in get
    return request('get', url, params=params, **kwargs)
  File "C:\Users\12139\AppData\Local\Programs\Python\Python37\lib\requests\api.py", line 61, in request
    return session.request(method=method, url=url, **kwargs)
  File "C:\Users\12139\AppData\Local\Programs\Python\Python37\lib\requests\sessions.py", line 521, in request
    prep.url, proxies, stream, verify, cert
  File "C:\Users\12139\AppData\Local\Programs\Python\Python37\lib\requests\sessions.py", line 696, in merge_environment_settings
    no_proxy = proxies.get('no_proxy') if proxies is not None else None
AttributeError: 'Proxy' object has no attribute 'get'
2021-02-21 23:30:26 httpbin_validator.py [line:104] ERROR: 'Proxy' object has no attribute 'get'
Traceback (most recent call last):
  File "D:/07python_auto/04IPProxyPool/core/proxy_validate/httpbin_validator.py", line 81, in _check_http_proxies
    response = requests.get(test_url,headers=get_request_headers(),proxies=proxies,timeout=TEST_TIMEOUT)
  File "C:\Users\12139\AppData\Local\Programs\Python\Python37\lib\requests\api.py", line 76, in get
    return request('get', url, params=params, **kwargs)
  File "C:\Users\12139\AppData\Local\Programs\Python\Python37\lib\requests\api.py", line 61, in request
    return session.request(method=method, url=url, **kwargs)
  File "C:\Users\12139\AppData\Local\Programs\Python\Python37\lib\requests\sessions.py", line 521, in request
    prep.url, proxies, stream, verify, cert
  File "C:\Users\12139\AppData\Local\Programs\Python\Python37\lib\requests\sessions.py", line 696, in merge_environment_settings
    no_proxy = proxies.get('no_proxy') if proxies is not None else None
AttributeError: 'Proxy' object has no attribute 'get'
2021-02-21 23:33:49 httpbin_validator.py [line:104] ERROR: HTTPConnectionPool(host='186.159.3.41', port=30334): Read timed out. (read timeout=10)
Traceback (most recent call last):
  File "C:\Users\12139\AppData\Local\Programs\Python\Python37\lib\urllib3\connectionpool.py", line 421, in _make_request
    six.raise_from(e, None)
  File "<string>", line 3, in raise_from
  File "C:\Users\12139\AppData\Local\Programs\Python\Python37\lib\urllib3\connectionpool.py", line 416, in _make_request
    httplib_response = conn.getresponse()
  File "C:\Users\12139\AppData\Local\Programs\Python\Python37\lib\http\client.py", line 1321, in getresponse
    response.begin()
  File "C:\Users\12139\AppData\Local\Programs\Python\Python37\lib\http\client.py", line 296, in begin
    version, status, reason = self._read_status()
  File "C:\Users\12139\AppData\Local\Programs\Python\Python37\lib\http\client.py", line 257, in _read_status
    line = str(self.fp.readline(_MAXLINE + 1), "iso-8859-1")
  File "C:\Users\12139\AppData\Local\Programs\Python\Python37\lib\socket.py", line 589, in readinto
    return self._sock.recv_into(b)
socket.timeout: timed out

During handling of the above exception, another exception occurred:

Traceback (most recent call last):
  File "C:\Users\12139\AppData\Local\Programs\Python\Python37\lib\requests\adapters.py", line 449, in send
    timeout=timeout
  File "C:\Users\12139\AppData\Local\Programs\Python\Python37\lib\urllib3\connectionpool.py", line 720, in urlopen
    method, url, error=e, _pool=self, _stacktrace=sys.exc_info()[2]
  File "C:\Users\12139\AppData\Local\Programs\Python\Python37\lib\urllib3\util\retry.py", line 400, in increment
    raise six.reraise(type(error), error, _stacktrace)
  File "C:\Users\12139\AppData\Local\Programs\Python\Python37\lib\urllib3\packages\six.py", line 735, in reraise
    raise value
  File "C:\Users\12139\AppData\Local\Programs\Python\Python37\lib\urllib3\connectionpool.py", line 672, in urlopen
    chunked=chunked,
  File "C:\Users\12139\AppData\Local\Programs\Python\Python37\lib\urllib3\connectionpool.py", line 423, in _make_request
    self._raise_timeout(err=e, url=url, timeout_value=read_timeout)
  File "C:\Users\12139\AppData\Local\Programs\Python\Python37\lib\urllib3\connectionpool.py", line 331, in _raise_timeout
    self, url, "Read timed out. (read timeout=%s)" % timeout_value
urllib3.exceptions.ReadTimeoutError: HTTPConnectionPool(host='186.159.3.41', port=30334): Read timed out. (read timeout=10)

During handling of the above exception, another exception occurred:

Traceback (most recent call last):
  File "D:/07python_auto/04IPProxyPool/core/proxy_validate/httpbin_validator.py", line 81, in _check_http_proxies
    response = requests.get(test_url,headers=get_request_headers(),proxies=proxies,timeout=TEST_TIMEOUT)
  File "C:\Users\12139\AppData\Local\Programs\Python\Python37\lib\requests\api.py", line 76, in get
    return request('get', url, params=params, **kwargs)
  File "C:\Users\12139\AppData\Local\Programs\Python\Python37\lib\requests\api.py", line 61, in request
    return session.request(method=method, url=url, **kwargs)
  File "C:\Users\12139\AppData\Local\Programs\Python\Python37\lib\requests\sessions.py", line 530, in request
    resp = self.send(prep, **send_kwargs)
  File "C:\Users\12139\AppData\Local\Programs\Python\Python37\lib\requests\sessions.py", line 643, in send
    r = adapter.send(request, **kwargs)
  File "C:\Users\12139\AppData\Local\Programs\Python\Python37\lib\requests\adapters.py", line 529, in send
    raise ReadTimeout(e, request=request)
requests.exceptions.ReadTimeout: HTTPConnectionPool(host='186.159.3.41', port=30334): Read timed out. (read timeout=10)
2021-02-21 23:33:59 httpbin_validator.py [line:104] ERROR: HTTPSConnectionPool(host='httpbin.org', port=443): Max retries exceeded with url: /get (Caused by ConnectTimeoutError(<urllib3.connection.VerifiedHTTPSConnection object at 0x0000013B13A057B8>, 'Connection to 186.159.3.41 timed out. (connect timeout=10)'))
Traceback (most recent call last):
  File "C:\Users\12139\AppData\Local\Programs\Python\Python37\lib\urllib3\connection.py", line 157, in _new_conn
    (self._dns_host, self.port), self.timeout, **extra_kw
  File "C:\Users\12139\AppData\Local\Programs\Python\Python37\lib\urllib3\util\connection.py", line 84, in create_connection
    raise err
  File "C:\Users\12139\AppData\Local\Programs\Python\Python37\lib\urllib3\util\connection.py", line 74, in create_connection
    sock.connect(sa)
socket.timeout: timed out

During handling of the above exception, another exception occurred:

Traceback (most recent call last):
  File "C:\Users\12139\AppData\Local\Programs\Python\Python37\lib\urllib3\connectionpool.py", line 662, in urlopen
    self._prepare_proxy(conn)
  File "C:\Users\12139\AppData\Local\Programs\Python\Python37\lib\urllib3\connectionpool.py", line 948, in _prepare_proxy
    conn.connect()
  File "C:\Users\12139\AppData\Local\Programs\Python\Python37\lib\urllib3\connection.py", line 334, in connect
    conn = self._new_conn()
  File "C:\Users\12139\AppData\Local\Programs\Python\Python37\lib\urllib3\connection.py", line 164, in _new_conn
    % (self.host, self.timeout),
urllib3.exceptions.ConnectTimeoutError: (<urllib3.connection.VerifiedHTTPSConnection object at 0x0000013B13A057B8>, 'Connection to 186.159.3.41 timed out. (connect timeout=10)')

During handling of the above exception, another exception occurred:

Traceback (most recent call last):
  File "C:\Users\12139\AppData\Local\Programs\Python\Python37\lib\requests\adapters.py", line 449, in send
    timeout=timeout
  File "C:\Users\12139\AppData\Local\Programs\Python\Python37\lib\urllib3\connectionpool.py", line 720, in urlopen
    method, url, error=e, _pool=self, _stacktrace=sys.exc_info()[2]
  File "C:\Users\12139\AppData\Local\Programs\Python\Python37\lib\urllib3\util\retry.py", line 436, in increment
    raise MaxRetryError(_pool, url, error or ResponseError(cause))
urllib3.exceptions.MaxRetryError: HTTPSConnectionPool(host='httpbin.org', port=443): Max retries exceeded with url: /get (Caused by ConnectTimeoutError(<urllib3.connection.VerifiedHTTPSConnection object at 0x0000013B13A057B8>, 'Connection to 186.159.3.41 timed out. (connect timeout=10)'))

During handling of the above exception, another exception occurred:

Traceback (most recent call last):
  File "D:/07python_auto/04IPProxyPool/core/proxy_validate/httpbin_validator.py", line 81, in _check_http_proxies
    response = requests.get(test_url,headers=get_request_headers(),proxies=proxies,timeout=TEST_TIMEOUT)
  File "C:\Users\12139\AppData\Local\Programs\Python\Python37\lib\requests\api.py", line 76, in get
    return request('get', url, params=params, **kwargs)
  File "C:\Users\12139\AppData\Local\Programs\Python\Python37\lib\requests\api.py", line 61, in request
    return session.request(method=method, url=url, **kwargs)
  File "C:\Users\12139\AppData\Local\Programs\Python\Python37\lib\requests\sessions.py", line 530, in request
    resp = self.send(prep, **send_kwargs)
  File "C:\Users\12139\AppData\Local\Programs\Python\Python37\lib\requests\sessions.py", line 643, in send
    r = adapter.send(request, **kwargs)
  File "C:\Users\12139\AppData\Local\Programs\Python\Python37\lib\requests\adapters.py", line 504, in send
    raise ConnectTimeout(e, request=request)
requests.exceptions.ConnectTimeout: HTTPSConnectionPool(host='httpbin.org', port=443): Max retries exceeded with url: /get (Caused by ConnectTimeoutError(<urllib3.connection.VerifiedHTTPSConnection object at 0x0000013B13A057B8>, 'Connection to 186.159.3.41 timed out. (connect timeout=10)'))
2021-02-21 23:34:23 httpbin_validator.py [line:104] ERROR: HTTPSConnectionPool(host='httpbin.org', port=443): Max retries exceeded with url: /get (Caused by ProxyError('Cannot connect to proxy.', timeout('timed out')))
Traceback (most recent call last):
  File "C:\Users\12139\AppData\Local\Programs\Python\Python37\lib\urllib3\connectionpool.py", line 662, in urlopen
    self._prepare_proxy(conn)
  File "C:\Users\12139\AppData\Local\Programs\Python\Python37\lib\urllib3\connectionpool.py", line 948, in _prepare_proxy
    conn.connect()
  File "C:\Users\12139\AppData\Local\Programs\Python\Python37\lib\urllib3\connection.py", line 342, in connect
    self._tunnel()
  File "C:\Users\12139\AppData\Local\Programs\Python\Python37\lib\http\client.py", line 906, in _tunnel
    (version, code, message) = response._read_status()
  File "C:\Users\12139\AppData\Local\Programs\Python\Python37\lib\http\client.py", line 257, in _read_status
    line = str(self.fp.readline(_MAXLINE + 1), "iso-8859-1")
  File "C:\Users\12139\AppData\Local\Programs\Python\Python37\lib\socket.py", line 589, in readinto
    return self._sock.recv_into(b)
socket.timeout: timed out

During handling of the above exception, another exception occurred:

Traceback (most recent call last):
  File "C:\Users\12139\AppData\Local\Programs\Python\Python37\lib\requests\adapters.py", line 449, in send
    timeout=timeout
  File "C:\Users\12139\AppData\Local\Programs\Python\Python37\lib\urllib3\connectionpool.py", line 720, in urlopen
    method, url, error=e, _pool=self, _stacktrace=sys.exc_info()[2]
  File "C:\Users\12139\AppData\Local\Programs\Python\Python37\lib\urllib3\util\retry.py", line 436, in increment
    raise MaxRetryError(_pool, url, error or ResponseError(cause))
urllib3.exceptions.MaxRetryError: HTTPSConnectionPool(host='httpbin.org', port=443): Max retries exceeded with url: /get (Caused by ProxyError('Cannot connect to proxy.', timeout('timed out')))

During handling of the above exception, another exception occurred:

Traceback (most recent call last):
  File "D:/07python_auto/04IPProxyPool/core/proxy_validate/httpbin_validator.py", line 81, in _check_http_proxies
    response = requests.get(test_url,headers=get_request_headers(),proxies=proxies,timeout=TEST_TIMEOUT)
  File "C:\Users\12139\AppData\Local\Programs\Python\Python37\lib\requests\api.py", line 76, in get
    return request('get', url, params=params, **kwargs)
  File "C:\Users\12139\AppData\Local\Programs\Python\Python37\lib\requests\api.py", line 61, in request
    return session.request(method=method, url=url, **kwargs)
  File "C:\Users\12139\AppData\Local\Programs\Python\Python37\lib\requests\sessions.py", line 530, in request
    resp = self.send(prep, **send_kwargs)
  File "C:\Users\12139\AppData\Local\Programs\Python\Python37\lib\requests\sessions.py", line 643, in send
    r = adapter.send(request, **kwargs)
  File "C:\Users\12139\AppData\Local\Programs\Python\Python37\lib\requests\adapters.py", line 510, in send
    raise ProxyError(e, request=request)
requests.exceptions.ProxyError: HTTPSConnectionPool(host='httpbin.org', port=443): Max retries exceeded with url: /get (Caused by ProxyError('Cannot connect to proxy.', timeout('timed out')))
2021-02-21 23:35:12 httpbin_validator.py [line:103] ERROR: HTTPConnectionPool(host='186.159.3.41', port=30334): Read timed out. (read timeout=10)
Traceback (most recent call last):
  File "C:\Users\12139\AppData\Local\Programs\Python\Python37\lib\urllib3\connectionpool.py", line 421, in _make_request
    six.raise_from(e, None)
  File "<string>", line 3, in raise_from
  File "C:\Users\12139\AppData\Local\Programs\Python\Python37\lib\urllib3\connectionpool.py", line 416, in _make_request
    httplib_response = conn.getresponse()
  File "C:\Users\12139\AppData\Local\Programs\Python\Python37\lib\http\client.py", line 1321, in getresponse
    response.begin()
  File "C:\Users\12139\AppData\Local\Programs\Python\Python37\lib\http\client.py", line 296, in begin
    version, status, reason = self._read_status()
  File "C:\Users\12139\AppData\Local\Programs\Python\Python37\lib\http\client.py", line 257, in _read_status
    line = str(self.fp.readline(_MAXLINE + 1), "iso-8859-1")
  File "C:\Users\12139\AppData\Local\Programs\Python\Python37\lib\socket.py", line 589, in readinto
    return self._sock.recv_into(b)
socket.timeout: timed out

During handling of the above exception, another exception occurred:

Traceback (most recent call last):
  File "C:\Users\12139\AppData\Local\Programs\Python\Python37\lib\requests\adapters.py", line 449, in send
    timeout=timeout
  File "C:\Users\12139\AppData\Local\Programs\Python\Python37\lib\urllib3\connectionpool.py", line 720, in urlopen
    method, url, error=e, _pool=self, _stacktrace=sys.exc_info()[2]
  File "C:\Users\12139\AppData\Local\Programs\Python\Python37\lib\urllib3\util\retry.py", line 400, in increment
    raise six.reraise(type(error), error, _stacktrace)
  File "C:\Users\12139\AppData\Local\Programs\Python\Python37\lib\urllib3\packages\six.py", line 735, in reraise
    raise value
  File "C:\Users\12139\AppData\Local\Programs\Python\Python37\lib\urllib3\connectionpool.py", line 672, in urlopen
    chunked=chunked,
  File "C:\Users\12139\AppData\Local\Programs\Python\Python37\lib\urllib3\connectionpool.py", line 423, in _make_request
    self._raise_timeout(err=e, url=url, timeout_value=read_timeout)
  File "C:\Users\12139\AppData\Local\Programs\Python\Python37\lib\urllib3\connectionpool.py", line 331, in _raise_timeout
    self, url, "Read timed out. (read timeout=%s)" % timeout_value
urllib3.exceptions.ReadTimeoutError: HTTPConnectionPool(host='186.159.3.41', port=30334): Read timed out. (read timeout=10)

During handling of the above exception, another exception occurred:

Traceback (most recent call last):
  File "D:/07python_auto/04IPProxyPool/core/proxy_validate/httpbin_validator.py", line 81, in _check_http_proxies
    response = requests.get(test_url,headers=get_request_headers(),proxies=proxies,timeout=TEST_TIMEOUT)
  File "C:\Users\12139\AppData\Local\Programs\Python\Python37\lib\requests\api.py", line 76, in get
    return request('get', url, params=params, **kwargs)
  File "C:\Users\12139\AppData\Local\Programs\Python\Python37\lib\requests\api.py", line 61, in request
    return session.request(method=method, url=url, **kwargs)
  File "C:\Users\12139\AppData\Local\Programs\Python\Python37\lib\requests\sessions.py", line 530, in request
    resp = self.send(prep, **send_kwargs)
  File "C:\Users\12139\AppData\Local\Programs\Python\Python37\lib\requests\sessions.py", line 643, in send
    r = adapter.send(request, **kwargs)
  File "C:\Users\12139\AppData\Local\Programs\Python\Python37\lib\requests\adapters.py", line 529, in send
    raise ReadTimeout(e, request=request)
requests.exceptions.ReadTimeout: HTTPConnectionPool(host='186.159.3.41', port=30334): Read timed out. (read timeout=10)
2021-02-22 23:01:09 httpbin_validator.py [line:103] ERROR: HTTPConnectionPool(host='186.159.3.41', port=30334): Max retries exceeded with url: http://httpbin.org/get (Caused by ConnectTimeoutError(<urllib3.connection.HTTPConnection object at 0x000001F22B378DA0>, 'Connection to 186.159.3.41 timed out. (connect timeout=10)'))
Traceback (most recent call last):
  File "C:\Users\12139\AppData\Local\Programs\Python\Python37\lib\urllib3\connection.py", line 157, in _new_conn
    (self._dns_host, self.port), self.timeout, **extra_kw
  File "C:\Users\12139\AppData\Local\Programs\Python\Python37\lib\urllib3\util\connection.py", line 84, in create_connection
    raise err
  File "C:\Users\12139\AppData\Local\Programs\Python\Python37\lib\urllib3\util\connection.py", line 74, in create_connection
    sock.connect(sa)
socket.timeout: timed out

During handling of the above exception, another exception occurred:

Traceback (most recent call last):
  File "C:\Users\12139\AppData\Local\Programs\Python\Python37\lib\urllib3\connectionpool.py", line 672, in urlopen
    chunked=chunked,
  File "C:\Users\12139\AppData\Local\Programs\Python\Python37\lib\urllib3\connectionpool.py", line 387, in _make_request
    conn.request(method, url, **httplib_request_kw)
  File "C:\Users\12139\AppData\Local\Programs\Python\Python37\lib\http\client.py", line 1229, in request
    self._send_request(method, url, body, headers, encode_chunked)
  File "C:\Users\12139\AppData\Local\Programs\Python\Python37\lib\http\client.py", line 1275, in _send_request
    self.endheaders(body, encode_chunked=encode_chunked)
  File "C:\Users\12139\AppData\Local\Programs\Python\Python37\lib\http\client.py", line 1224, in endheaders
    self._send_output(message_body, encode_chunked=encode_chunked)
  File "C:\Users\12139\AppData\Local\Programs\Python\Python37\lib\http\client.py", line 1016, in _send_output
    self.send(msg)
  File "C:\Users\12139\AppData\Local\Programs\Python\Python37\lib\http\client.py", line 956, in send
    self.connect()
  File "C:\Users\12139\AppData\Local\Programs\Python\Python37\lib\urllib3\connection.py", line 184, in connect
    conn = self._new_conn()
  File "C:\Users\12139\AppData\Local\Programs\Python\Python37\lib\urllib3\connection.py", line 164, in _new_conn
    % (self.host, self.timeout),
urllib3.exceptions.ConnectTimeoutError: (<urllib3.connection.HTTPConnection object at 0x000001F22B378DA0>, 'Connection to 186.159.3.41 timed out. (connect timeout=10)')

During handling of the above exception, another exception occurred:

Traceback (most recent call last):
  File "C:\Users\12139\AppData\Local\Programs\Python\Python37\lib\requests\adapters.py", line 449, in send
    timeout=timeout
  File "C:\Users\12139\AppData\Local\Programs\Python\Python37\lib\urllib3\connectionpool.py", line 720, in urlopen
    method, url, error=e, _pool=self, _stacktrace=sys.exc_info()[2]
  File "C:\Users\12139\AppData\Local\Programs\Python\Python37\lib\urllib3\util\retry.py", line 436, in increment
    raise MaxRetryError(_pool, url, error or ResponseError(cause))
urllib3.exceptions.MaxRetryError: HTTPConnectionPool(host='186.159.3.41', port=30334): Max retries exceeded with url: http://httpbin.org/get (Caused by ConnectTimeoutError(<urllib3.connection.HTTPConnection object at 0x000001F22B378DA0>, 'Connection to 186.159.3.41 timed out. (connect timeout=10)'))

During handling of the above exception, another exception occurred:

Traceback (most recent call last):
  File "D:/07python_auto/04IPProxyPool/core/proxy_validate/httpbin_validator.py", line 81, in _check_http_proxies
    response = requests.get(test_url,headers=get_request_headers(),proxies=proxies,timeout=TEST_TIMEOUT)
  File "C:\Users\12139\AppData\Local\Programs\Python\Python37\lib\requests\api.py", line 76, in get
    return request('get', url, params=params, **kwargs)
  File "C:\Users\12139\AppData\Local\Programs\Python\Python37\lib\requests\api.py", line 61, in request
    return session.request(method=method, url=url, **kwargs)
  File "C:\Users\12139\AppData\Local\Programs\Python\Python37\lib\requests\sessions.py", line 530, in request
    resp = self.send(prep, **send_kwargs)
  File "C:\Users\12139\AppData\Local\Programs\Python\Python37\lib\requests\sessions.py", line 643, in send
    r = adapter.send(request, **kwargs)
  File "C:\Users\12139\AppData\Local\Programs\Python\Python37\lib\requests\adapters.py", line 504, in send
    raise ConnectTimeout(e, request=request)
requests.exceptions.ConnectTimeout: HTTPConnectionPool(host='186.159.3.41', port=30334): Max retries exceeded with url: http://httpbin.org/get (Caused by ConnectTimeoutError(<urllib3.connection.HTTPConnection object at 0x000001F22B378DA0>, 'Connection to 186.159.3.41 timed out. (connect timeout=10)'))
2021-02-22 23:01:19 httpbin_validator.py [line:103] ERROR: HTTPSConnectionPool(host='httpbin.org', port=443): Max retries exceeded with url: /get (Caused by ConnectTimeoutError(<urllib3.connection.VerifiedHTTPSConnection object at 0x000001F22B3A8F28>, 'Connection to 186.159.3.41 timed out. (connect timeout=10)'))
Traceback (most recent call last):
  File "C:\Users\12139\AppData\Local\Programs\Python\Python37\lib\urllib3\connection.py", line 157, in _new_conn
    (self._dns_host, self.port), self.timeout, **extra_kw
  File "C:\Users\12139\AppData\Local\Programs\Python\Python37\lib\urllib3\util\connection.py", line 84, in create_connection
    raise err
  File "C:\Users\12139\AppData\Local\Programs\Python\Python37\lib\urllib3\util\connection.py", line 74, in create_connection
    sock.connect(sa)
socket.timeout: timed out

During handling of the above exception, another exception occurred:

Traceback (most recent call last):
  File "C:\Users\12139\AppData\Local\Programs\Python\Python37\lib\urllib3\connectionpool.py", line 662, in urlopen
    self._prepare_proxy(conn)
  File "C:\Users\12139\AppData\Local\Programs\Python\Python37\lib\urllib3\connectionpool.py", line 948, in _prepare_proxy
    conn.connect()
  File "C:\Users\12139\AppData\Local\Programs\Python\Python37\lib\urllib3\connection.py", line 334, in connect
    conn = self._new_conn()
  File "C:\Users\12139\AppData\Local\Programs\Python\Python37\lib\urllib3\connection.py", line 164, in _new_conn
    % (self.host, self.timeout),
urllib3.exceptions.ConnectTimeoutError: (<urllib3.connection.VerifiedHTTPSConnection object at 0x000001F22B3A8F28>, 'Connection to 186.159.3.41 timed out. (connect timeout=10)')

During handling of the above exception, another exception occurred:

Traceback (most recent call last):
  File "C:\Users\12139\AppData\Local\Programs\Python\Python37\lib\requests\adapters.py", line 449, in send
    timeout=timeout
  File "C:\Users\12139\AppData\Local\Programs\Python\Python37\lib\urllib3\connectionpool.py", line 720, in urlopen
    method, url, error=e, _pool=self, _stacktrace=sys.exc_info()[2]
  File "C:\Users\12139\AppData\Local\Programs\Python\Python37\lib\urllib3\util\retry.py", line 436, in increment
    raise MaxRetryError(_pool, url, error or ResponseError(cause))
urllib3.exceptions.MaxRetryError: HTTPSConnectionPool(host='httpbin.org', port=443): Max retries exceeded with url: /get (Caused by ConnectTimeoutError(<urllib3.connection.VerifiedHTTPSConnection object at 0x000001F22B3A8F28>, 'Connection to 186.159.3.41 timed out. (connect timeout=10)'))

During handling of the above exception, another exception occurred:

Traceback (most recent call last):
  File "D:/07python_auto/04IPProxyPool/core/proxy_validate/httpbin_validator.py", line 81, in _check_http_proxies
    response = requests.get(test_url,headers=get_request_headers(),proxies=proxies,timeout=TEST_TIMEOUT)
  File "C:\Users\12139\AppData\Local\Programs\Python\Python37\lib\requests\api.py", line 76, in get
    return request('get', url, params=params, **kwargs)
  File "C:\Users\12139\AppData\Local\Programs\Python\Python37\lib\requests\api.py", line 61, in request
    return session.request(method=method, url=url, **kwargs)
  File "C:\Users\12139\AppData\Local\Programs\Python\Python37\lib\requests\sessions.py", line 530, in request
    resp = self.send(prep, **send_kwargs)
  File "C:\Users\12139\AppData\Local\Programs\Python\Python37\lib\requests\sessions.py", line 643, in send
    r = adapter.send(request, **kwargs)
  File "C:\Users\12139\AppData\Local\Programs\Python\Python37\lib\requests\adapters.py", line 504, in send
    raise ConnectTimeout(e, request=request)
requests.exceptions.ConnectTimeout: HTTPSConnectionPool(host='httpbin.org', port=443): Max retries exceeded with url: /get (Caused by ConnectTimeoutError(<urllib3.connection.VerifiedHTTPSConnection object at 0x000001F22B3A8F28>, 'Connection to 186.159.3.41 timed out. (connect timeout=10)'))
2021-02-22 23:04:06 httpbin_validator.py [line:103] ERROR: HTTPConnectionPool(host='186.159.3.41', port=30334): Max retries exceeded with url: http://httpbin.org/get (Caused by ConnectTimeoutError(<urllib3.connection.HTTPConnection object at 0x0000025BF168AD30>, 'Connection to 186.159.3.41 timed out. (connect timeout=10)'))
Traceback (most recent call last):
  File "C:\Users\12139\AppData\Local\Programs\Python\Python37\lib\urllib3\connection.py", line 157, in _new_conn
    (self._dns_host, self.port), self.timeout, **extra_kw
  File "C:\Users\12139\AppData\Local\Programs\Python\Python37\lib\urllib3\util\connection.py", line 84, in create_connection
    raise err
  File "C:\Users\12139\AppData\Local\Programs\Python\Python37\lib\urllib3\util\connection.py", line 74, in create_connection
    sock.connect(sa)
socket.timeout: timed out

During handling of the above exception, another exception occurred:

Traceback (most recent call last):
  File "C:\Users\12139\AppData\Local\Programs\Python\Python37\lib\urllib3\connectionpool.py", line 672, in urlopen
    chunked=chunked,
  File "C:\Users\12139\AppData\Local\Programs\Python\Python37\lib\urllib3\connectionpool.py", line 387, in _make_request
    conn.request(method, url, **httplib_request_kw)
  File "C:\Users\12139\AppData\Local\Programs\Python\Python37\lib\http\client.py", line 1229, in request
    self._send_request(method, url, body, headers, encode_chunked)
  File "C:\Users\12139\AppData\Local\Programs\Python\Python37\lib\http\client.py", line 1275, in _send_request
    self.endheaders(body, encode_chunked=encode_chunked)
  File "C:\Users\12139\AppData\Local\Programs\Python\Python37\lib\http\client.py", line 1224, in endheaders
    self._send_output(message_body, encode_chunked=encode_chunked)
  File "C:\Users\12139\AppData\Local\Programs\Python\Python37\lib\http\client.py", line 1016, in _send_output
    self.send(msg)
  File "C:\Users\12139\AppData\Local\Programs\Python\Python37\lib\http\client.py", line 956, in send
    self.connect()
  File "C:\Users\12139\AppData\Local\Programs\Python\Python37\lib\urllib3\connection.py", line 184, in connect
    conn = self._new_conn()
  File "C:\Users\12139\AppData\Local\Programs\Python\Python37\lib\urllib3\connection.py", line 164, in _new_conn
    % (self.host, self.timeout),
urllib3.exceptions.ConnectTimeoutError: (<urllib3.connection.HTTPConnection object at 0x0000025BF168AD30>, 'Connection to 186.159.3.41 timed out. (connect timeout=10)')

During handling of the above exception, another exception occurred:

Traceback (most recent call last):
  File "C:\Users\12139\AppData\Local\Programs\Python\Python37\lib\requests\adapters.py", line 449, in send
    timeout=timeout
  File "C:\Users\12139\AppData\Local\Programs\Python\Python37\lib\urllib3\connectionpool.py", line 720, in urlopen
    method, url, error=e, _pool=self, _stacktrace=sys.exc_info()[2]
  File "C:\Users\12139\AppData\Local\Programs\Python\Python37\lib\urllib3\util\retry.py", line 436, in increment
    raise MaxRetryError(_pool, url, error or ResponseError(cause))
urllib3.exceptions.MaxRetryError: HTTPConnectionPool(host='186.159.3.41', port=30334): Max retries exceeded with url: http://httpbin.org/get (Caused by ConnectTimeoutError(<urllib3.connection.HTTPConnection object at 0x0000025BF168AD30>, 'Connection to 186.159.3.41 timed out. (connect timeout=10)'))

During handling of the above exception, another exception occurred:

Traceback (most recent call last):
  File "D:/07python_auto/04IPProxyPool/core/proxy_validate/httpbin_validator.py", line 81, in _check_http_proxies
    response = requests.get(test_url,headers=get_request_headers(),proxies=proxies,timeout=TEST_TIMEOUT)
  File "C:\Users\12139\AppData\Local\Programs\Python\Python37\lib\requests\api.py", line 76, in get
    return request('get', url, params=params, **kwargs)
  File "C:\Users\12139\AppData\Local\Programs\Python\Python37\lib\requests\api.py", line 61, in request
    return session.request(method=method, url=url, **kwargs)
  File "C:\Users\12139\AppData\Local\Programs\Python\Python37\lib\requests\sessions.py", line 530, in request
    resp = self.send(prep, **send_kwargs)
  File "C:\Users\12139\AppData\Local\Programs\Python\Python37\lib\requests\sessions.py", line 643, in send
    r = adapter.send(request, **kwargs)
  File "C:\Users\12139\AppData\Local\Programs\Python\Python37\lib\requests\adapters.py", line 504, in send
    raise ConnectTimeout(e, request=request)
requests.exceptions.ConnectTimeout: HTTPConnectionPool(host='186.159.3.41', port=30334): Max retries exceeded with url: http://httpbin.org/get (Caused by ConnectTimeoutError(<urllib3.connection.HTTPConnection object at 0x0000025BF168AD30>, 'Connection to 186.159.3.41 timed out. (connect timeout=10)'))
2021-02-22 23:04:16 httpbin_validator.py [line:103] ERROR: HTTPSConnectionPool(host='httpbin.org', port=443): Max retries exceeded with url: /get (Caused by ConnectTimeoutError(<urllib3.connection.VerifiedHTTPSConnection object at 0x0000025BF16BAEF0>, 'Connection to 186.159.3.41 timed out. (connect timeout=10)'))
Traceback (most recent call last):
  File "C:\Users\12139\AppData\Local\Programs\Python\Python37\lib\urllib3\connection.py", line 157, in _new_conn
    (self._dns_host, self.port), self.timeout, **extra_kw
  File "C:\Users\12139\AppData\Local\Programs\Python\Python37\lib\urllib3\util\connection.py", line 84, in create_connection
    raise err
  File "C:\Users\12139\AppData\Local\Programs\Python\Python37\lib\urllib3\util\connection.py", line 74, in create_connection
    sock.connect(sa)
socket.timeout: timed out

During handling of the above exception, another exception occurred:

Traceback (most recent call last):
  File "C:\Users\12139\AppData\Local\Programs\Python\Python37\lib\urllib3\connectionpool.py", line 662, in urlopen
    self._prepare_proxy(conn)
  File "C:\Users\12139\AppData\Local\Programs\Python\Python37\lib\urllib3\connectionpool.py", line 948, in _prepare_proxy
    conn.connect()
  File "C:\Users\12139\AppData\Local\Programs\Python\Python37\lib\urllib3\connection.py", line 334, in connect
    conn = self._new_conn()
  File "C:\Users\12139\AppData\Local\Programs\Python\Python37\lib\urllib3\connection.py", line 164, in _new_conn
    % (self.host, self.timeout),
urllib3.exceptions.ConnectTimeoutError: (<urllib3.connection.VerifiedHTTPSConnection object at 0x0000025BF16BAEF0>, 'Connection to 186.159.3.41 timed out. (connect timeout=10)')

During handling of the above exception, another exception occurred:

Traceback (most recent call last):
  File "C:\Users\12139\AppData\Local\Programs\Python\Python37\lib\requests\adapters.py", line 449, in send
    timeout=timeout
  File "C:\Users\12139\AppData\Local\Programs\Python\Python37\lib\urllib3\connectionpool.py", line 720, in urlopen
    method, url, error=e, _pool=self, _stacktrace=sys.exc_info()[2]
  File "C:\Users\12139\AppData\Local\Programs\Python\Python37\lib\urllib3\util\retry.py", line 436, in increment
    raise MaxRetryError(_pool, url, error or ResponseError(cause))
urllib3.exceptions.MaxRetryError: HTTPSConnectionPool(host='httpbin.org', port=443): Max retries exceeded with url: /get (Caused by ConnectTimeoutError(<urllib3.connection.VerifiedHTTPSConnection object at 0x0000025BF16BAEF0>, 'Connection to 186.159.3.41 timed out. (connect timeout=10)'))

During handling of the above exception, another exception occurred:

Traceback (most recent call last):
  File "D:/07python_auto/04IPProxyPool/core/proxy_validate/httpbin_validator.py", line 81, in _check_http_proxies
    response = requests.get(test_url,headers=get_request_headers(),proxies=proxies,timeout=TEST_TIMEOUT)
  File "C:\Users\12139\AppData\Local\Programs\Python\Python37\lib\requests\api.py", line 76, in get
    return request('get', url, params=params, **kwargs)
  File "C:\Users\12139\AppData\Local\Programs\Python\Python37\lib\requests\api.py", line 61, in request
    return session.request(method=method, url=url, **kwargs)
  File "C:\Users\12139\AppData\Local\Programs\Python\Python37\lib\requests\sessions.py", line 530, in request
    resp = self.send(prep, **send_kwargs)
  File "C:\Users\12139\AppData\Local\Programs\Python\Python37\lib\requests\sessions.py", line 643, in send
    r = adapter.send(request, **kwargs)
  File "C:\Users\12139\AppData\Local\Programs\Python\Python37\lib\requests\adapters.py", line 504, in send
    raise ConnectTimeout(e, request=request)
requests.exceptions.ConnectTimeout: HTTPSConnectionPool(host='httpbin.org', port=443): Max retries exceeded with url: /get (Caused by ConnectTimeoutError(<urllib3.connection.VerifiedHTTPSConnection object at 0x0000025BF16BAEF0>, 'Connection to 186.159.3.41 timed out. (connect timeout=10)'))
2021-02-22 23:05:03 httpbin_validator.py [line:103] ERROR: HTTPConnectionPool(host='118.175.93.103', port=48214): Read timed out. (read timeout=10)
Traceback (most recent call last):
  File "C:\Users\12139\AppData\Local\Programs\Python\Python37\lib\urllib3\connectionpool.py", line 421, in _make_request
    six.raise_from(e, None)
  File "<string>", line 3, in raise_from
  File "C:\Users\12139\AppData\Local\Programs\Python\Python37\lib\urllib3\connectionpool.py", line 416, in _make_request
    httplib_response = conn.getresponse()
  File "C:\Users\12139\AppData\Local\Programs\Python\Python37\lib\http\client.py", line 1321, in getresponse
    response.begin()
  File "C:\Users\12139\AppData\Local\Programs\Python\Python37\lib\http\client.py", line 296, in begin
    version, status, reason = self._read_status()
  File "C:\Users\12139\AppData\Local\Programs\Python\Python37\lib\http\client.py", line 257, in _read_status
    line = str(self.fp.readline(_MAXLINE + 1), "iso-8859-1")
  File "C:\Users\12139\AppData\Local\Programs\Python\Python37\lib\socket.py", line 589, in readinto
    return self._sock.recv_into(b)
socket.timeout: timed out

During handling of the above exception, another exception occurred:

Traceback (most recent call last):
  File "C:\Users\12139\AppData\Local\Programs\Python\Python37\lib\requests\adapters.py", line 449, in send
    timeout=timeout
  File "C:\Users\12139\AppData\Local\Programs\Python\Python37\lib\urllib3\connectionpool.py", line 720, in urlopen
    method, url, error=e, _pool=self, _stacktrace=sys.exc_info()[2]
  File "C:\Users\12139\AppData\Local\Programs\Python\Python37\lib\urllib3\util\retry.py", line 400, in increment
    raise six.reraise(type(error), error, _stacktrace)
  File "C:\Users\12139\AppData\Local\Programs\Python\Python37\lib\urllib3\packages\six.py", line 735, in reraise
    raise value
  File "C:\Users\12139\AppData\Local\Programs\Python\Python37\lib\urllib3\connectionpool.py", line 672, in urlopen
    chunked=chunked,
  File "C:\Users\12139\AppData\Local\Programs\Python\Python37\lib\urllib3\connectionpool.py", line 423, in _make_request
    self._raise_timeout(err=e, url=url, timeout_value=read_timeout)
  File "C:\Users\12139\AppData\Local\Programs\Python\Python37\lib\urllib3\connectionpool.py", line 331, in _raise_timeout
    self, url, "Read timed out. (read timeout=%s)" % timeout_value
urllib3.exceptions.ReadTimeoutError: HTTPConnectionPool(host='118.175.93.103', port=48214): Read timed out. (read timeout=10)

During handling of the above exception, another exception occurred:

Traceback (most recent call last):
  File "D:/07python_auto/04IPProxyPool/core/proxy_validate/httpbin_validator.py", line 81, in _check_http_proxies
    response = requests.get(test_url,headers=get_request_headers(),proxies=proxies,timeout=TEST_TIMEOUT)
  File "C:\Users\12139\AppData\Local\Programs\Python\Python37\lib\requests\api.py", line 76, in get
    return request('get', url, params=params, **kwargs)
  File "C:\Users\12139\AppData\Local\Programs\Python\Python37\lib\requests\api.py", line 61, in request
    return session.request(method=method, url=url, **kwargs)
  File "C:\Users\12139\AppData\Local\Programs\Python\Python37\lib\requests\sessions.py", line 530, in request
    resp = self.send(prep, **send_kwargs)
  File "C:\Users\12139\AppData\Local\Programs\Python\Python37\lib\requests\sessions.py", line 643, in send
    r = adapter.send(request, **kwargs)
  File "C:\Users\12139\AppData\Local\Programs\Python\Python37\lib\requests\adapters.py", line 529, in send
    raise ReadTimeout(e, request=request)
requests.exceptions.ReadTimeout: HTTPConnectionPool(host='118.175.93.103', port=48214): Read timed out. (read timeout=10)
2021-02-22 23:05:13 httpbin_validator.py [line:103] ERROR: HTTPSConnectionPool(host='httpbin.org', port=443): Max retries exceeded with url: /get (Caused by ConnectTimeoutError(<urllib3.connection.VerifiedHTTPSConnection object at 0x0000021D4BB83828>, 'Connection to 118.175.93.103 timed out. (connect timeout=10)'))
Traceback (most recent call last):
  File "C:\Users\12139\AppData\Local\Programs\Python\Python37\lib\urllib3\connection.py", line 157, in _new_conn
    (self._dns_host, self.port), self.timeout, **extra_kw
  File "C:\Users\12139\AppData\Local\Programs\Python\Python37\lib\urllib3\util\connection.py", line 84, in create_connection
    raise err
  File "C:\Users\12139\AppData\Local\Programs\Python\Python37\lib\urllib3\util\connection.py", line 74, in create_connection
    sock.connect(sa)
socket.timeout: timed out

During handling of the above exception, another exception occurred:

Traceback (most recent call last):
  File "C:\Users\12139\AppData\Local\Programs\Python\Python37\lib\urllib3\connectionpool.py", line 662, in urlopen
    self._prepare_proxy(conn)
  File "C:\Users\12139\AppData\Local\Programs\Python\Python37\lib\urllib3\connectionpool.py", line 948, in _prepare_proxy
    conn.connect()
  File "C:\Users\12139\AppData\Local\Programs\Python\Python37\lib\urllib3\connection.py", line 334, in connect
    conn = self._new_conn()
  File "C:\Users\12139\AppData\Local\Programs\Python\Python37\lib\urllib3\connection.py", line 164, in _new_conn
    % (self.host, self.timeout),
urllib3.exceptions.ConnectTimeoutError: (<urllib3.connection.VerifiedHTTPSConnection object at 0x0000021D4BB83828>, 'Connection to 118.175.93.103 timed out. (connect timeout=10)')

During handling of the above exception, another exception occurred:

Traceback (most recent call last):
  File "C:\Users\12139\AppData\Local\Programs\Python\Python37\lib\requests\adapters.py", line 449, in send
    timeout=timeout
  File "C:\Users\12139\AppData\Local\Programs\Python\Python37\lib\urllib3\connectionpool.py", line 720, in urlopen
    method, url, error=e, _pool=self, _stacktrace=sys.exc_info()[2]
  File "C:\Users\12139\AppData\Local\Programs\Python\Python37\lib\urllib3\util\retry.py", line 436, in increment
    raise MaxRetryError(_pool, url, error or ResponseError(cause))
urllib3.exceptions.MaxRetryError: HTTPSConnectionPool(host='httpbin.org', port=443): Max retries exceeded with url: /get (Caused by ConnectTimeoutError(<urllib3.connection.VerifiedHTTPSConnection object at 0x0000021D4BB83828>, 'Connection to 118.175.93.103 timed out. (connect timeout=10)'))

During handling of the above exception, another exception occurred:

Traceback (most recent call last):
  File "D:/07python_auto/04IPProxyPool/core/proxy_validate/httpbin_validator.py", line 81, in _check_http_proxies
    response = requests.get(test_url,headers=get_request_headers(),proxies=proxies,timeout=TEST_TIMEOUT)
  File "C:\Users\12139\AppData\Local\Programs\Python\Python37\lib\requests\api.py", line 76, in get
    return request('get', url, params=params, **kwargs)
  File "C:\Users\12139\AppData\Local\Programs\Python\Python37\lib\requests\api.py", line 61, in request
    return session.request(method=method, url=url, **kwargs)
  File "C:\Users\12139\AppData\Local\Programs\Python\Python37\lib\requests\sessions.py", line 530, in request
    resp = self.send(prep, **send_kwargs)
  File "C:\Users\12139\AppData\Local\Programs\Python\Python37\lib\requests\sessions.py", line 643, in send
    r = adapter.send(request, **kwargs)
  File "C:\Users\12139\AppData\Local\Programs\Python\Python37\lib\requests\adapters.py", line 504, in send
    raise ConnectTimeout(e, request=request)
requests.exceptions.ConnectTimeout: HTTPSConnectionPool(host='httpbin.org', port=443): Max retries exceeded with url: /get (Caused by ConnectTimeoutError(<urllib3.connection.VerifiedHTTPSConnection object at 0x0000021D4BB83828>, 'Connection to 118.175.93.103 timed out. (connect timeout=10)'))
